Workbook
Name Ad_Month: Market!$A$2:$A$553
Name Ad_Region: Market!$D$2:$D$553
Name Ad_Spend: Market!$F$2:$F$553
Name Ad_State: Market!$B$2:$B$553
Name Ad_State_Code: Market!$C$2:$C$553
Name Ad_Year: Market!$E$2:$E$553
Name Category: Orders!$O$2:$O$4834
Name cCat: Analysis!$B$7
Name cChannel: Analysis!$B$6
Name City: Orders!$K$2:$K$4834
Name COGS: Orders!$W$2:$W$4834
Name cRegion: Analysis!$B$5
Name Customer_ID: Orders!$F$2:$F$4834
Name Customer_Rating: Orders!$AE$2:$AE$4834
Name Customer_Type: Orders!$G$2:$G$4834
Name cYear: Analysis!$B$4
Name Delivery_Date: Orders!$AB$2:$AB$4834
Name Delivery_Days: Orders!$AC$2:$AC$4834
Name Delivery_Speed: Orders!$AD$2:$AD$4834
Name Discount_Amount: Orders!$T$2:$T$4834
Name Discount_Clean2: Orders!$R$2:$R$4834
Name Gross_Sale: Orders!$S$2:$S$4834
Name Margin: Orders!$Z$2:$Z$4834
Name Month: Orders!$D$2:$D$4834
Name Month_No: Orders!$E$2:$E$4834
Name Net_Revenue: Orders!$U$2:$U$4834
Name Order_Date: Orders!$B$2:$B$4834
Name Order_ID: Orders!$A$2:$A$4834
Name Payment_Method: Orders!$AA$2:$AA$4834
Name Product_ID: Orders!$M$2:$M$4834
Name Product_Name: Orders!$N$2:$N$4834
Name Profit: Orders!$Y$2:$Y$4834
Name Quantity: Orders!$P$2:$P$4834
Name Region: Orders!$J$2:$J$4834
Name Returned: Orders!$AF$2:$AF$4834
Name Sales_Channel: Orders!$L$2:$L$4834
Name selCategory: Dashboard!$P$5
Name selChannel: Dashboard!$L$5
Name selMetric: Dashboard!$T$5
Name selRegion: Dashboard!$H$5
Name selTopN: Dashboard!$X$5
Name selYear: Dashboard!$D$5
Name Shipping_Cost: Orders!$X$2:$X$4834
Name Slicer_Category: #N/A
Name Slicer_Region: #N/A
Name Slicer_Sales_Channel: #N/A
Name State: Orders!$H$2:$H$4834
Name State_Code: Orders!$I$2:$I$4834
Name Unit_Cost: Orders!$V$2:$V$4834
Name Unit_Price: Orders!$Q$2:$Q$4834
Name Year: Orders!$C$2:$C$4834

Sheet Detail2
A1: Details for Sum of Net Revenue - Months (Order Date): Mar, Quarters (Order Date): Qtr1, Years (Order Date): 2024
A3: Order ID | B3: Order Date | C3: Year | D3: Month | E3: Month No | F3: Customer ID | G3: Customer Type | H3: State | I3: State Code | J3: Region | K3: City | L3: Sales Channel | M3: Product ID | N3: Product Name | O3: Category | P3: Quantity | Q3: Unit Price | R3: Discount % | S3: Gross Sale | T3: Discount Amount | U3: Net Revenue | V3: Unit Cost | W3: COGS | X3: Shipping Cost | Y3: Profit Margin | Z3: Margin % | AA3: Payment Method | AB3: Delivery Date | AC3: Delivery Days | AD3: Delivery Speed | AE3: Customer Rating | AF3: Returned
A4: ORD-100297 | B4: 45352 | C4: 2024 | D4: 45352 | E4: 3 | F4: CUST-00404 | G4: New | H4: Karnataka | I4: KA | J4: South | K4: Mysuru | L4: Flipkart | M4: P404 | N4: Flip Flops | O4: Footwear | P4: 1 | Q4: 399 | R4: 0.05 | S4: 399 | T4: 19.95 | U4: 379.05 | V4: 152 | W4: 152 | X4: 60 | Y4: 167.05 | Z4: 0.44070703 | AA4: Credit Card | AB4: 45355 | AC4: 3 | AD4: Standard (3-4d) | AE4: 5 | AF4: 0
A5: ORD-100296 | B5: 45352 | C5: 2024 | D5: 45352 | E5: 3 | F5: CUST-00103 | G5: New | H5: Odisha | I5: OD | J5: East | K5: Bhubaneswar | L5: Amazon | M5: P101 | N5: Vitamin C Face Serum | O5: Skincare | P5: 2 | Q5: 599 | R5: 0.2 | S5: 1198 | T5: 239.6 | U5: 958.4 | V5: 180 | W5: 360 | X5: 60 | Y5: 538.4 | Z5: 0.56176962 | AA5: UPI | AB5: 45355 | AC5: 3 | AD5: Standard (3-4d) | AE5: 4 | AF5: 0
A6: ORD-100295 | B6: 45352 | C6: 2024 | D6: 45352 | E6: 3 | F6: CUST-01121 | G6: New | H6: Telangana | I6: TG | J6: South | K6: Hyderabad | L6: Amazon | M6: P203 | N6: Keratin Hair Mask | O6: Haircare | P6: 1 | Q6: 549 | R6: 0.2 | S6: 549 | T6: 109.8 | U6: 439.2 | V6: 170 | W6: 170 | X6: 60 | Y6: 209.2 | Z6: 0.47632058 | AA6: COD | AB6: 45354 | AC6: 2 | AD6: Express (≤2d) | AE6: 4 | AF6: 0
A7: ORD-100294 | B7: 45352 | C7: 2024 | D7: 45352 | E7: 3 | F7: CUST-01990 | G7: New | H7: Maharashtra | I7: MH | J7: West | K7: Mumbai | L7: Myntra | M7: P301 | N7: Cotton Oversized T-Shirt | O7: Apparel | P7: 1 | Q7: 799 | R7: 0.1 | S7: 799 | T7: 79.9 | U7: 719.1 | V7: 320 | W7: 320 | X7: 60 | Y7: 339.1 | Z7: 0.47156167 | AA7: Wallet | AB7: 45353 | AC7: 1 | AD7: Express (≤2d) | AE7: 4 | AF7: 0
A8: ORD-100293 | B8: 45352 | C8: 2024 | D8: 45352 | E8: 3 | F8: CUST-01052 | G8: New | H8: West Bengal | I8: WB | J8: East | K8: Kolkata | L8: Flipkart | M8: P303 | N8: Joggers | O8: Apparel | P8: 1 | Q8: 1199 | R8: 0.05 | S8: 1199 | T8: 59.95 | U8: 1139.05 | V8: 492 | W8: 492 | X8: 120 | Y8: 527.05 | Z8: 0.46271015 | AA8: COD | AB8: 45353 | AC8: 1 | AD8: Express (≤2d) | AF8: 1
A9: ORD-100292 | B9: 45352 | C9: 2024 | D9: 45352 | E9: 3 | F9: CUST-03067 | G9: New | H9: Madhya Pradesh | I9: MP | J9: West | K9: Bhopal | L9: Website | M9: P702 | N9: Whey Protein 1kg | O9: Wellness | P9: 1 | Q9: 2299 | R9: 0.25 | S9: 2299 | T9: 574.75 | U9: 1724.25 | V9: 1333 | W9: 1333 | X9: 60 | Y9: 331.25 | Z9: 0.19211251 | AA9: Wallet | AB9: 45356 | AC9: 4 | AD9: Standard (3-4d) | AE9: 4 | AF9: 0
A10: ORD-100300 | B10: 45353 | C10: 2024 | D10: 45352 | E10: 3 | F10: CUST-00943 | G10: New | H10: Tamil Nadu | I10: TN | J10: South | K10: Chennai | L10: Myntra | M10: P404 | N10: Flip Flops | O10: Footwear | P10: 1 | Q10: 399 | R10: 0.15 | S10: 399 | T10: 59.85 | U10: 339.15 | V10: 152 | W10: 152 | X10: 60 | Y10: 127.15 | Z10: 0.37490786 | AA10: UPI | AB10: 45355 | AC10: 2 | AD10: Express (≤2d) | AE10: 5 | AF10: 0
A11: ORD-100299 | B11: 45353 | C11: 2024 | D11: 45352 | E11: 3 | F11: CUST-01058 | G11: New | H11: Kerala | I11: KL | J11: South | K11: Thiruvananthapuram | L11: Amazon | M11: P501 | N11: Copper Water Bottle | O11: Home & Kitchen | P11: 1 | Q11: 899 | R11: 0.05 | S11: 899 | T11: 44.95 | U11: 854.05 | V11: 378 | W11: 378 | X11: 120 | Y11: 356.05 | Z11: 0.41689597 | AA11: COD | AB11: 45357 | AC11: 4 | AD11: Standard (3-4d) | AE11: 4 | AF11: 1
A12: ORD-100298 | B12: 45353 | C12: 2024 | D12: 45352 | E12: 3 | F12: CUST-00530 | G12: New | H12: Maharashtra | I12: MH | J12: West | K12: Pune | L12: Flipkart | M12: P303 | N12: Joggers | O12: Apparel | P12: 1 | Q12: 1199 | R12: 0.2 | S12: 1199 | T12: 239.8 | U12: 959.2 | V12: 492 | W12: 492 | X12: 60 | Y12: 407.2 | Z12: 0.42452043 | AA12: UPI | AB12: 45355 | AC12: 2 | AD12: Express (≤2d) | AE12: 3 | AF12: 0
A13: ORD-100304 | B13: 45354 | C13: 2024 | D13: 45352 | E13: 3 | F13: CUST-00728 | G13: New | H13: Karnataka | I13: KA | J13: South | K13: Bengaluru | L13: Nykaa | M13: P701 | N13: Ashwagandha Capsules | O13: Wellness | P13: 1 | Q13: 499 | R13: 0 | S13: 499 | T13: 0 | U13: 499 | V13: 150 | W13: 150 | X13: 60 | Y13: 289 | Z13: 0.57915832 | AA13: COD | AB13: 45357 | AC13: 3 | AD13: Standard (3-4d) | AE13: 4 | AF13: 0
A14: ORD-100303 | B14: 45354 | C14: 2024 | D14: 45352 | E14: 3 | F14: CUST-00295 | G14: New | H14: Maharashtra | I14: MH | J14: West | K14: Pune | L14: Myntra | M14: P303 | N14: Joggers | O14: Apparel | P14: 2 | Q14: 1199 | R14: 0.15 | S14: 2398 | T14: 359.7 | U14: 2038.3 | V14: 492 | W14: 984 | X14: 60 | Y14: 994.3 | Z14: 0.48780847 | AA14: Credit Card | AB14: 45357 | AC14: 3 | AD14: Standard (3-4d) | AE14: 4 | AF14: 0
A15: ORD-100302 | B15: 45354 | C15: 2024 | D15: 45352 | E15: 3 | F15: CUST-02092 | G15: New | H15: West Bengal | I15: WB | J15: East | K15: Kolkata | L15: Amazon | M15: P303 | N15: Joggers | O15: Apparel | P15: 3 | Q15: 1199 | R15: 0.2 | S15: 3597 | T15: 719.4 | U15: 2877.6 | V15: 492 | W15: 1476 | X15: 120 | Y15: 1281.6 | Z15: 0.44537114 | AA15: Debit Card | AB15: 45356 | AC15: 2 | AD15: Express (≤2d) | AF15: 1
A16: ORD-100301 | B16: 45354 | C16: 2024 | D16: 45352 | E16: 3 | F16: CUST-00832 | G16: New | H16: Delhi | I16: DL | J16: North | K16: New Delhi | L16: Myntra | M16: P401 | N16: Running Shoes | O16: Footwear | P16: 1 | Q16: 2999 | R16: 0.2 | S16: 2999 | T16: 599.8 | U16: 2399.2 | V16: 1440 | W16: 1440 | X16: 60 | Y16: 899.2 | Z16: 0.3747916 | AA16: Debit Card | AB16: 45356 | AC16: 2 | AD16: Express (≤2d) | AE16: 4 | AF16: 0
A17: ORD-100308 | B17: 45355 | C17: 2024 | D17: 45352 | E17: 3 | F17: CUST-02052 | G17: New | H17: West Bengal | I17: WB | J17: East | K17: Kolkata | L17: Myntra | M17: P302 | N17: Linen Kurta | O17: Apparel | P17: 2 | Q17: 1499 | R17: 0.4 | S17: 2998 | T17: 1199.2 | U17: 1798.8 | V17: 630 | W17: 1260 | X17: 60 | Y17: 478.8 | Z17: 0.26617745 | AA17: Debit Card | AB17: 45359 | AC17: 4 | AD17: Standard (3-4d) | AE17: 3 | AF17: 0
A18: ORD-100307 | B18: 45355 | C18: 2024 | D18: 45352 | E18: 3 | F18: CUST-00021 | G18: New | H18: Chhattisgarh | I18: CG | J18: East | K18: Raipur | L18: Website | M18: P602 | N18: Fast Charger 33W | O18: Electronics | P18: 1 | Q18: 899 | R18: 0 | S18: 899 | T18: 0 | U18: 899 | V18: 494 | W18: 494 | X18: 60 | Y18: 345 | Z18: 0.38375973 | AA18: COD | AB18: 45359 | AC18: 4 | AD18: Standard (3-4d) | AE18: 4 | AF18: 0
A19: ORD-100306 | B19: 45355 | C19: 2024 | D19: 45352 | E19: 3 | F19: CUST-00831 | G19: Repeat | H19: Uttar Pradesh | I19: UP | J19: North | K19: Lucknow | L19: Amazon | M19: P501 | N19: Copper Water Bottle | O19: Home & Kitchen | P19: 2 | Q19: 899 | R19: 0.05 | S19: 1798 | T19: 89.9 | U19: 1708.1 | V19: 378 | W19: 756 | X19: 120 | Y19: 832.1 | Z19: 0.48714946 | AA19: UPI | AB19: 45359 | AC19: 4 | AD19: Standard (3-4d) | AF19: 1
A20: ORD-100305 | B20: 45355 | C20: 2024 | D20: 45352 | E20: 3 | F20: CUST-01098 | G20: New | H20: Rajasthan | I20: RJ | J20: North | K20: Udaipur | L20: Amazon | M20: P702 | N20: Whey Protein 1kg | O20: Wellness | P20: 2 | Q20: 2299 | R20: 0.4 | S20: 4598 | T20: 1839.2 | U20: 2758.8 | V20: 1333 | W20: 2666 | X20: 60 | Y20: 32.8 | Z20: 0.011889227 | AA20: COD | AB20: 45360 | AC20: 5 | AD20: Delayed (5d+) | AE20: 3 | AF20: 0
A21: ORD-100311 | B21: 45356 | C21: 2024 | D21: 45352 | E21: 3 | F21: CUST-03156 | G21: New | H21: West Bengal | I21: WB | J21: East | K21: Kolkata | L21: Flipkart | M21: P404 | N21: Flip Flops | O21: Footwear | P21: 1 | Q21: 399 | R21: 0.1 | S21: 399 | T21: 39.9 | U21: 359.1 | V21: 152 | W21: 152 | X21: 60 | Y21: 147.1 | Z21: 0.4096352 | AA21: Credit Card | AB21: 45361 | AC21: 5 | AD21: Delayed (5d+) | AE21: 3 | AF21: 0
A22: ORD-100310 | B22: 45356 | C22: 2024 | D22: 45352 | E22: 3 | F22: CUST-00628 | G22: New | H22: Madhya Pradesh | I22: MP | J22: West | K22: Indore | L22: Myntra | M22: P302 | N22: Linen Kurta | O22: Apparel | P22: 2 | Q22: 1499 | R22: 0.4 | S22: 2998 | T22: 1199.2 | U22: 1798.8 | V22: 630 | W22: 1260 | X22: 60 | Y22: 478.8 | Z22: 0.26617745 | AA22: COD | AB22: 45359 | AC22: 3 | AD22: Standard (3-4d) | AF22: 0
A23: ORD-100309 | B23: 45356 | C23: 2024 | D23: 45352 | E23: 3 | F23: CUST-01054 | G23: New | H23: Delhi | I23: DL | J23: North | K23: New Delhi | L23: Amazon | M23: P603 | N23: Smartwatch Strap | O23: Electronics | P23: 1 | Q23: 499 | R23: 0.05 | S23: 499 | T23: 24.95 | U23: 474.05 | V23: 200 | W23: 200 | X23: 60 | Y23: 214.05 | Z23: 0.45153465 | AA23: Credit Card | AB23: 45359 | AC23: 3 | AD23: Standard (3-4d) | AE23: 3 | AF23: 0
A24: ORD-100316 | B24: 45357 | C24: 2024 | D24: 45352 | E24: 3 | F24: CUST-02384 | G24: New | H24: Maharashtra | I24: MH | J24: West | K24: Nagpur | L24: Amazon | M24: P104 | N24: Hydrating Face Wash | O24: Skincare | P24: 3 | Q24: 299 | R24: 0 | S24: 897 | T24: 0 | U24: 897 | V24: 90 | W24: 270 | X24: 60 | Y24: 567 | Z24: 0.63210702 | AA24: UPI | AB24: 45358 | AC24: 1 | AD24: Express (≤2d) | AE24: 5 | AF24: 0
A25: ORD-100315 | B25: 45357 | C25: 2024 | D25: 45352 | E25: 3 | F25: CUST-00390 | G25: New | H25: West Bengal | I25: WB | J25: East | K25: Kolkata | L25: Nykaa | M25: P701 | N25: Ashwagandha Capsules | O25: Wellness | P25: 2 | Q25: 499 | R25: 0.05 | S25: 998 | T25: 49.9 | U25: 948.1 | V25: 150 | W25: 300 | X25: 60 | Y25: 588.1 | Z25: 0.62029322 | AA25: UPI | AB25: 45360 | AC25: 3 | AD25: Standard (3-4d) | AE25: 5 | AF25: 0
A26: ORD-100314 | B26: 45357 | C26: 2024 | D26: 45352 | E26: 3 | F26: CUST-00141 | G26: New | H26: Uttar Pradesh | I26: UP | J26: North | K26: Kanpur | L26: Website | M26: P103 | N26: Niacinamide Toner | O26: Skincare | P26: 1 | Q26: 399 | R26: 0.15 | S26: 399 | T26: 59.85 | U26: 339.15 | V26: 112 | W26: 112 | X26: 60 | Y26: 167.15 | Z26: 0.49284977 | AA26: Credit Card | AB26: 45362 | AC26: 5 | AD26: Delayed (5d+) | AE26: 4 | AF26: 0
A27: ORD-100313 | B27: 45357 | C27: 2024 | D27: 45352 | E27: 3 | F27: CUST-00182 | G27: Repeat | H27: Delhi | I27: DL | J27: North | K27: New Delhi | L27: Flipkart | M27: P105 | N27: Retinol Night Cream | O27: Skincare | P27: 1 | Q27: 799 | R27: 0.1 | S27: 799 | T27: 79.9 | U27: 719.1 | V27: 216 | W27: 216 | X27: 60 | Y27: 443.1 | Z27: 0.6161869 | AA27: Debit Card | AB27: 45358 | AC27: 1 | AD27: Express (≤2d) | AE27: 4 | AF27: 0
A28: ORD-100312 | B28: 45357 | C28: 2024 | D28: 45352 | E28: 3 | F28: CUST-02085 | G28: New | H28: Himachal Pradesh | I28: HP | J28: North | K28: Shimla | L28: Amazon | M28: P204 | N28: Anti-Dandruff Conditioner | O28: Haircare | P28: 2 | Q28: 399 | R28: 0.3 | S28: 798 | T28: 239.4 | U28: 558.6 | V28: 136 | W28: 272 | X28: 60 | Y28: 226.6 | Z28: 0.405657 | AA28: UPI | AB28: 45360 | AC28: 3 | AD28: Standard (3-4d) | AE28: 4 | AF28: 0
A29: ORD-100321 | B29: 45358 | C29: 2024 | D29: 45352 | E29: 3 | F29: CUST-00602 | G29: New | H29: Gujarat | I29: GJ | J29: West | K29: Surat | L29: Flipkart | M29: P602 | N29: Fast Charger 33W | O29: Electronics | P29: 2 | Q29: 899 | R29: 0.05 | S29: 1798 | T29: 89.9 | U29: 1708.1 | V29: 494 | W29: 988 | X29: 60 | Y29: 660.1 | Z29: 0.38645278 | AA29: COD | AB29: 45361 | AC29: 3 | AD29: Standard (3-4d) | AE29: 5 | AF29: 0
A30: ORD-100320 | B30: 45358 | C30: 2024 | D30: 45352 | E30: 3 | F30: CUST-00297 | G30: Repeat | H30: Delhi | I30: DL | J30: North | K30: New Delhi | L30: Amazon | M30: P102 | N30: Sunscreen SPF 50 | O30: Skincare | P30: 1 | Q30: 449 | R30: 0.1 | S30: 449 | T30: 44.9 | U30: 404.1 | V30: 144 | W30: 144 | X30: 60 | Y30: 200.1 | Z30: 0.49517446 | AA30: UPI | AB30: 45359 | AC30: 1 | AD30: Express (≤2d) | AF30: 0
A31: ORD-100319 | B31: 45358 | C31: 2024 | D31: 45352 | E31: 3 | F31: CUST-01047 | G31: New | H31: Delhi | I31: DL | J31: North | K31: New Delhi | L31: Nykaa | M31: P102 | N31: Sunscreen SPF 50 | O31: Skincare | P31: 1 | Q31: 449 | R31: 0.05 | S31: 449 | T31: 22.45 | U31: 426.55 | V31: 144 | W31: 144 | X31: 60 | Y31: 222.55 | Z31: 0.52174423 | AA31: Debit Card | AB31: 45359 | AC31: 1 | AD31: Express (≤2d) | AE31: 5 | AF31: 0
A32: ORD-100318 | B32: 45358 | C32: 2024 | D32: 45352 | E32: 3 | F32: CUST-02389 | G32: New | H32: Haryana | I32: HR | J32: North | K32: Faridabad | L32: Amazon | M32: P404 | N32: Flip Flops | O32: Footwear | P32: 1 | Q32: 399 | R32: 0.15 | S32: 399 | T32: 59.85 | U32: 339.15 | V32: 152 | W32: 152 | X32: 120 | Y32: 67.15 | Z32: 0.19799499 | AA32: UPI | AB32: 45360 | AC32: 2 | AD32: Express (≤2d) | AE32: 5 | AF32: 1
A33: ORD-100317 | B33: 45358 | C33: 2024 | D33: 45352 | E33: 3 | F33: CUST-00991 | G33: Repeat | H33: Rajasthan | I33: RJ | J33: North | K33: Udaipur | L33: Flipkart | M33: P404 | N33: Flip Flops | O33: Footwear | P33: 4 | Q33: 399 | R33: 0.05 | S33: 1596 | T33: 79.8 | U33: 1516.2 | V33: 152 | W33: 608 | X33: 60 | Y33: 848.2 | Z33: 0.55942488 | AA33: UPI | AB33: 45362 | AC33: 4 | AD33: Standard (3-4d) | AF33: 0
A34: ORD-100325 | B34: 45359 | C34: 2024 | D34: 45352 | E34: 3 | F34: CUST-01148 | G34: New | H34: Telangana | I34: TG | J34: South | K34: Hyderabad | L34: Website | M34: P704 | N34: Multivitamin Gummies | O34: Wellness | P34: 2 | Q34: 699 | R34: 0.15 | S34: 1398 | T34: 209.7 | U34: 1188.3 | V34: 238 | W34: 476 | X34: 60 | Y34: 652.3 | Z34: 0.54893545 | AA34: UPI | AB34: 45363 | AC34: 4 | AD34: Standard (3-4d) | AF34: 0
A35: ORD-100324 | B35: 45359 | C35: 2024 | D35: 45352 | E35: 3 | F35: CUST-00170 | G35: New | H35: West Bengal | I35: WB | J35: East | K35: Kolkata | L35: Nykaa | M35: P701 | N35: Ashwagandha Capsules | O35: Wellness | P35: 3 | Q35: 499 | R35: 0.1 | S35: 1497 | T35: 149.7 | U35: 1347.3 | V35: 150 | W35: 450 | X35: 60 | Y35: 837.3 | Z35: 0.62146515 | AA35: COD | AB35: 45362 | AC35: 3 | AD35: Standard (3-4d) | AE35: 4 | AF35: 0
A36: ORD-100323 | B36: 45359 | C36: 2024 | D36: 45352 | E36: 3 | F36: CUST-01664 | G36: New | H36: West Bengal | I36: WB | J36: East | K36: Kolkata | L36: Website | M36: P105 | N36: Retinol Night Cream | O36: Skincare | P36: 1 | Q36: 799 | R36: 0 | S36: 799 | T36: 0 | U36: 799 | V36: 216 | W36: 216 | X36: 60 | Y36: 523 | Z36: 0.65456821 | AA36: COD | AB36: 45361 | AC36: 2 | AD36: Express (≤2d) | AE36: 4 | AF36: 0
A37: ORD-100322 | B37: 45359 | C37: 2024 | D37: 45352 | E37: 3 | F37: CUST-00687 | G37: New | H37: Assam | I37: AS | J37: East | K37: Guwahati | L37: Myntra | M37: P302 | N37: Linen Kurta | O37: Apparel | P37: 1 | Q37: 1499 | R37: 0.4 | S37: 1499 | T37: 599.6 | U37: 899.4 | V37: 630 | W37: 630 | X37: 60 | Y37: 209.4 | Z37: 0.23282188 | AA37: UPI | AB37: 45364 | AC37: 5 | AD37: Delayed (5d+) | AE37: 2 | AF37: 0
A38: ORD-100329 | B38: 45360 | C38: 2024 | D38: 45352 | E38: 3 | F38: CUST-02065 | G38: New | H38: Andhra Pradesh | I38: AP | J38: South | K38: Visakhapatnam | L38: Amazon | M38: P701 | N38: Ashwagandha Capsules | O38: Wellness | P38: 1 | Q38: 499 | R38: 0 | S38: 499 | T38: 0 | U38: 499 | V38: 150 | W38: 150 | X38: 120 | Y38: 229 | Z38: 0.45891784 | AA38: COD | AB38: 45365 | AC38: 5 | AD38: Delayed (5d+) | AE38: 4 | AF38: 1
A39: ORD-100328 | B39: 45360 | C39: 2024 | D39: 45352 | E39: 3 | F39: CUST-02148 | G39: New | H39: Telangana | I39: TG | J39: South | K39: Hyderabad | L39: Amazon | M39: P302 | N39: Linen Kurta | O39: Apparel | P39: 2 | Q39: 1499 | R39: 0.4 | S39: 2998 | T39: 1199.2 | U39: 1798.8 | V39: 630 | W39: 1260 | X39: 60 | Y39: 478.8 | Z39: 0.26617745 | AA39: Credit Card | AB39: 45361 | AC39: 1 | AD39: Express (≤2d) | AE39: 5 | AF39: 0
A40: ORD-100327 | B40: 45360 | C40: 2024 | D40: 45352 | E40: 3 | F40: CUST-03160 | G40: New | H40: West Bengal | I40: WB | J40: East | K40: Kolkata | L40: Myntra | M40: P301 | N40: Cotton Oversized T-Shirt | O40: Apparel | P40: 1 | Q40: 799 | R40: 0 | S40: 799 | T40: 0 | U40: 799 | V40: 320 | W40: 320 | X40: 60 | Y40: 419 | Z40: 0.52440551 | AA40: UPI | AB40: 45361 | AC40: 1 | AD40: Express (≤2d) | AE40: 5 | AF40: 0
A41: ORD-100326 | B41: 45360 | C41: 2024 | D41: 45352 | E41: 3 | F41: CUST-02599 | G41: New | H41: Delhi | I41: DL | J41: North | K41: New Delhi | L41: Amazon | M41: P402 | N41: Casual Sneakers | O41: Footwear | P41: 1 | Q41: 2199 | R41: 0.2 | S41: 2199 | T41: 439.8 | U41: 1759.2 | V41: 1034 | W41: 1034 | X41: 60 | Y41: 665.2 | Z41: 0.37812642 | AA41: Debit Card | AB41: 45363 | AC41: 3 | AD41: Standard (3-4d) | AE41: 4 | AF41: 0
...

Sheet Dashboard
B1: SHOPKART D2C | E-COMMERCE SALES & CUSTOMER ANALYTICS DASHBOARD (2024–2025)
B3: ="Showing: "&IF(selYear="All","2024–2025",selYear)&" • Region: "&selRegion&" • Channel: "&selChannel&" • Category: "&selCategory&" • "&TEXT(Analysis!B14,"#,##0")&" orders" -> Showing: 2024–2025 • Region: All • Channel: All • Category: All • 4,833 orders
D4: ▼ YEAR | H4: ▼REGION | L4: ▼SALES CHANNEL | P4: ▼CATEGORY | T4: ▼MAP METRIC | X4: ▼TOP N PRODUCTS
D5: All | H5: All | L5: All | P5: All | T5: Return Rate % | X5: 15
B7: REVENUE | E7: PROFIT | H7: PROFIT MARGIN | K7: ORDERS | N7: AVG ORDER VALUE | Q7: AVG RATING ★ | T7: RETURN RATE | W7: AVG DELIVERY (DAYS)
B8: =Analysis!B11 -> 5156142.5 | E8: =Analysis!B12 -> 2083254.5 | H8: =Analysis!B13 -> 0.40403353 | K8: =Analysis!B14 -> 4833 | N8: =Analysis!B16 -> 1066.8617 | Q8: =Analysis!B17 -> 3.9144603 | T8: =Analysis!B18 -> 0.10407614 | W8: =Analysis!B19 -> 3.3279537
B10: =IF(Analysis!E11="","",Analysis!E11) -> 0.28487949 | E10: =Analysis!E12 -> 0.29280918 | H10: =Analysis!E13 -> 0.002484889 | K10: =Analysis!E14 -> 0.27328316 | N10: =Analysis!E16 -> 0.0091074218 | Q10: =Analysis!E17 -> -0.010029005 | T10: =Analysis!E18 -> -0.0081745143 | W10: =Analysis!E19 -> -0.0048459779
B12: ▲▼ = 2025 vs 2024 for the same Region/Channel/Category
B13: SALES TREND
B31: PRODUCT & CHANNEL MIX
B49: GEOGRAPHY – INDIA TILE MAP & MARKETING EFFICIENCY
B50: ="India map – "&selMetric&" " -> India map – Return Rate %
G51: =INDEX(Analysis!$L$122:$L$144,MATCH("JK",Analysis!$B$122:$B$144,0)) -> 15.625
F52: =INDEX(Analysis!$L$122:$L$144,MATCH("PB",Analysis!$B$122:$B$144,0)) -> 11.363636 | G52: =INDEX(Analysis!$L$122:$L$144,MATCH("HP",Analysis!$B$122:$B$144,0)) -> 20 | H52: =INDEX(Analysis!$L$122:$L$144,MATCH("UK",Analysis!$B$122:$B$144,0)) -> 1.5151515
E53: =INDEX(Analysis!$L$122:$L$144,MATCH("RJ",Analysis!$B$122:$B$144,0)) -> 9.9236641 | F53: =INDEX(Analysis!$L$122:$L$144,MATCH("HR",Analysis!$B$122:$B$144,0)) -> 9.1954023 | G53: =INDEX(Analysis!$L$122:$L$144,MATCH("DL",Analysis!$B$122:$B$144,0)) -> 9.3150685 | H53: =INDEX(Analysis!$L$122:$L$144,MATCH("UP",Analysis!$B$122:$B$144,0)) -> 10.364146 | I53: =INDEX(Analysis!$L$122:$L$144,MATCH("BR",Analysis!$B$122:$B$144,0)) -> 8.3333333 | K53: =INDEX(Analysis!$L$122:$L$144,MATCH("AS",Analysis!$B$122:$B$144,0)) -> 12.987013
D54: =INDEX(Analysis!$L$122:$L$144,MATCH("GJ",Analysis!$B$122:$B$144,0)) -> 14.114114 | F54: =INDEX(Analysis!$L$122:$L$144,MATCH("MP",Analysis!$B$122:$B$144,0)) -> 12.062257 | G54: =INDEX(Analysis!$L$122:$L$144,MATCH("CG",Analysis!$B$122:$B$144,0)) -> 15.584416 | H54: =INDEX(Analysis!$L$122:$L$144,MATCH("JH",Analysis!$B$122:$B$144,0)) -> 12.345679 | I54: =INDEX(Analysis!$L$122:$L$144,MATCH("WB",Analysis!$B$122:$B$144,0)) -> 8.3601286
E55: =INDEX(Analysis!$L$122:$L$144,MATCH("MH",Analysis!$B$122:$B$144,0)) -> 10.344828 | F55: =INDEX(Analysis!$L$122:$L$144,MATCH("TG",Analysis!$B$122:$B$144,0)) -> 11.067194 | H55: =INDEX(Analysis!$L$122:$L$144,MATCH("OD",Analysis!$B$122:$B$144,0)) -> 10.11236
E56: =INDEX(Analysis!$L$122:$L$144,MATCH("GA",Analysis!$B$122:$B$144,0)) -> 8.6206897 | F56: =INDEX(Analysis!$L$122:$L$144,MATCH("KA",Analysis!$B$122:$B$144,0)) -> 7.3417722 | G56: =INDEX(Analysis!$L$122:$L$144,MATCH("AP",Analysis!$B$122:$B$144,0)) -> 11.27451
F57: =INDEX(Analysis!$L$122:$L$144,MATCH("KL",Analysis!$B$122:$B$144,0)) -> 8.7912088 | G57: =INDEX(Analysis!$L$122:$L$144,MATCH("TN",Analysis!$B$122:$B$144,0)) -> 11.111111
C58: ="🏆 Highest "&selMetric&": "&INDEX(Analysis!$A$122:$A$144,MATCH(MAX(Analysis!$L$122:$L$144),Analysis!$L$122:$L$144,0))&" ⚠ Lowest "&selMetric&": "&INDEX(Analysis!$A$122:$A$144,MATCH(MIN(Analysis!$L$122:$L$144),Analysis!$L$122:$L$144,0)) -> 🏆 Highest Return Rate %: Himachal Pradesh ⚠ Lowest Return Rate %: Uttarakhand | M58: =IF(OR(selChannel<>"All",selCategory<>"All"),"Select All channels and categories for overall advertising analysis.",IFERROR("Across states, each additional ₹1 of ad spend is associated with ₹"&TEXT(Analysis!B147,"0.00")&" of revenue change. R² = "&TEXT(Analysis!B149,"0.00")&"; r = "&TEXT(Analysis!B150,"0.00")&". Region filter ignored.","Insufficient data for advertising analysis.")) -> Across states, each additional ₹1 of ad spend is associated with ₹4.38 of revenue change. R² = 0.99; r = 0.99. Region filter ignored.
B59: CUSTOMER EXPERIENCE – DELIVERY, RATINGS & RETURNS
B81: PROFITABILITY – DISCOUNTS & PAYMENT BEHAVIOUR
B101: =IF(OR(Analysis!B190="",Analysis!B191=""),"Insufficient data to estimate the discount–margin relationship.","Each +10 percentage points of discount is associated with "&TEXT(Analysis!B190*10,"+0.0;-0.0;0.0")&" margin points (R² "&TEXT(Analysis!B191,"0.00")&").") -> Each +10 percentage points of discount is associated with -10.5 margin points (R² 0.59).
B102: CATEGORY - MONTH & CHANNEL SCORECARD
B103: Category | D103: Jan | E103: Feb | F103: Mar | G103: Apr | H103: May | I103: Jun | J103: Jul | K103: Aug | L103: Sep | M103: Oct | N103: Nov | O103: Dec | Q103: =Analysis!A79 -> Channel | R103: =Analysis!B79 -> Revenue | S103: =Analysis!H79 -> Share % | T103: =Analysis!D79 -> Margin % | U103: Return % | V103: Rating | W103: Avg Disc %
B104: Skincare | D104: =Analysis!B96 -> 56494.2 | E104: =Analysis!C96 -> 44310.05 | F104: =Analysis!D96 -> 43426.05 | G104: =Analysis!E96 -> 56952.45 | H104: =Analysis!F96 -> 40215.3 | I104: =Analysis!G96 -> 42008.25 | J104: =Analysis!H96 -> 45046.95 | K104: =Analysis!I96 -> 47870 | ... O104: =Analysis!M96 -> 51003.35 | Q104: =Analysis!A80 -> Amazon | R104: =Analysis!B80 -> 1447389.7 | S104: =Analysis!H80 -> 0.28071174 | T104: =Analysis!D80 -> 0.38105612 | U104: =Analysis!F80 -> 0.11072423 | V104: =Analysis!G80 -> 3.9414683 | W104: =Analysis!I80 -> 0.23660599
B105: Haircare | C105: Haircare | D105: =Analysis!B97 -> 24364.15 | E105: =Analysis!C97 -> 27617.2 | F105: =Analysis!D97 -> 25422.3 | G105: =Analysis!E97 -> 34087.5 | H105: =Analysis!F97 -> 27512.8 | I105: =Analysis!G97 -> 32450.4 | J105: =Analysis!H97 -> 30616.3 | K105: =Analysis!I97 -> 38731.9 | ... O105: =Analysis!M97 -> 45629.8 | Q105: =Analysis!A81 -> Flipkart | R105: =Analysis!B81 -> 1180727.3 | S105: =Analysis!H81 -> 0.22899432 | T105: =Analysis!D81 -> 0.39024704 | U105: =Analysis!F81 -> 0.094405594 | V105: =Analysis!G81 -> 3.9167658 | W105: =Analysis!I81 -> 0.22718366
B106: Apparel | C106: Apparel | D106: =Analysis!B98 -> 136340 | E106: =Analysis!C98 -> 86478.95 | F106: =Analysis!D98 -> 140923.35 | G106: =Analysis!E98 -> 115921.2 | H106: =Analysis!F98 -> 98493.35 | I106: =Analysis!G98 -> 117220.7 | J106: =Analysis!H98 -> 99421.05 | K106: =Analysis!I98 -> 82505.7 | ... O106: =Analysis!M98 -> 117284.95 | Q106: =Analysis!A82 -> Website | R106: =Analysis!B82 -> 914734.45 | S106: =Analysis!H82 -> 0.17740675 | T106: =Analysis!D82 -> 0.42344688 | U106: =Analysis!F82 -> 0.094951923 | V106: =Analysis!G82 -> 3.8010471 | W106: =Analysis!I82 -> 0.17940355
B107: Footwear | C107: Footwear | D107: =Analysis!B99 -> 93629.8 | E107: =Analysis!C99 -> 52408 | F107: =Analysis!D99 -> 68164.9 | G107: =Analysis!E99 -> 62253.4 | H107: =Analysis!F99 -> 64323.8 | I107: =Analysis!G99 -> 73525.15 | J107: =Analysis!H99 -> 70950.35 | K107: =Analysis!I99 -> 76241 | ... O107: =Analysis!M99 -> 91036.95 | Q107: =Analysis!A83 -> Myntra | R107: =Analysis!B83 -> 1162695.9 | S107: =Analysis!H83 -> 0.22549723 | T107: =Analysis!D83 -> 0.41746932 | U107: =Analysis!F83 -> 0.14049587 | V107: =Analysis!G83 -> 4 | W107: =Analysis!I83 -> 0.1975935
B108: Home & Kitchen | C108: Home & Kitchen | D108: =Analysis!B100 -> 57522.55 | E108: =Analysis!C100 -> 35114.3 | F108: =Analysis!D100 -> 57594.35 | G108: =Analysis!E100 -> 61113.65 | H108: =Analysis!F100 -> 41554 | I108: =Analysis!G100 -> 34798.3 | J108: =Analysis!H100 -> 29631.65 | K108: =Analysis!I100 -> 36695.1 | ... O108: =Analysis!M100 -> 42850.7 | Q108: =Analysis!A84 -> Nykaa | R108: =Analysis!B84 -> 450595.1 | S108: =Analysis!H84 -> 0.087389963 | T108: =Analysis!D84 -> 0.43988738 | U108: =Analysis!F84 -> 0.079136691 | V108: =Analysis!G84 -> 3.8969697 | W108: =Analysis!I84 -> 0.24173387
B109: Electronics | C109: Electronics | D109: =Analysis!B101 -> 41145.15 | E109: =Analysis!C101 -> 20743.45 | F109: =Analysis!D101 -> 30318.35 | G109: =Analysis!E101 -> 26749.7 | H109: =Analysis!F101 -> 32747.55 | I109: =Analysis!G101 -> 36285.25 | J109: =Analysis!H101 -> 39309.75 | K109: =Analysis!I101 -> 46878.75 | ... O109: =Analysis!M101 -> 28466.5
B110: Wellness | C110: Wellness | D110: =Analysis!B102 -> 61986.55 | E110: =Analysis!C102 -> 21309.15 | F110: =Analysis!D102 -> 48593.4 | G110: =Analysis!E102 -> 56784.5 | H110: =Analysis!F102 -> 36962.8 | I110: =Analysis!G102 -> 55240.2 | J110: =Analysis!H102 -> 46515.3 | K110: =Analysis!I102 -> 50153.7 | ... O110: =Analysis!M102 -> 68061.95
B112: TOP PRODUCTS PERFORMANCE & LEADERBOARD
B113: # | C113: Product | F113: Category | H113: Revenue | J113: Profit | K113: Margin % | L113: Units | M113: Rating | N113: Return % | O113: 24-Month Revenue Trend | R113: Monthly revenue
B114: =IF(Analysis!$K195,Analysis!A195,"") -> 1 | C114: =IF(Analysis!$K195,Analysis!B195,"") -> Linen Kurta | F114: =IF(Analysis!$K195,Analysis!C195,"") -> Apparel | H114: =IF(Analysis!$K195,Analysis!D195,"") -> 361333.95 | J114: =IF(Analysis!$K195,Analysis!E195,"") -> 111673.95 | K114: =IF(Analysis!$K195,Analysis!F195,"") -> 0.30906022 | L114: =IF(Analysis!$K195,Analysis!G195,"") -> 374 | M114: =IF(Analysis!$K195,Analysis!H195,"") -> 3.8407643 | N114: =IF(Analysis!$K195,Analysis!I195,"") -> 0.125
B115: =IF(Analysis!$K196,Analysis!A196,"") -> 2 | C115: =IF(Analysis!$K196,Analysis!B196,"") -> Running Shoes | F115: =IF(Analysis!$K196,Analysis!C196,"") -> Footwear | H115: =IF(Analysis!$K196,Analysis!D196,"") -> 346234.55 | J115: =IF(Analysis!$K196,Analysis!E196,"") -> 118354.55 | K115: =IF(Analysis!$K196,Analysis!F196,"") -> 0.34183345 | L115: =IF(Analysis!$K196,Analysis!G196,"") -> 153 | M115: =IF(Analysis!$K196,Analysis!H196,"") -> 3.8536585 | N115: =IF(Analysis!$K196,Analysis!I196,"") -> 0.18867925
B116: =IF(Analysis!$K197,Analysis!A197,"") -> 3 | C116: =IF(Analysis!$K197,Analysis!B197,"") -> Denim Jacket | F116: =IF(Analysis!$K197,Analysis!C197,"") -> Apparel | H116: =IF(Analysis!$K197,Analysis!D197,"") -> 310500.75 | J116: =IF(Analysis!$K197,Analysis!E197,"") -> 153795.75 | K116: =IF(Analysis!$K197,Analysis!F197,"") -> 0.49531523 | L116: =IF(Analysis!$K197,Analysis!G197,"") -> 133 | M116: =IF(Analysis!$K197,Analysis!H197,"") -> 3.9864865 | N116: =IF(Analysis!$K197,Analysis!I197,"") -> 0.18
B117: =IF(Analysis!$K198,Analysis!A198,"") -> 4 | C117: =IF(Analysis!$K198,Analysis!B198,"") -> Joggers | F117: =IF(Analysis!$K198,Analysis!C198,"") -> Apparel | H117: =IF(Analysis!$K198,Analysis!D198,"") -> 301908.2 | J117: =IF(Analysis!$K198,Analysis!E198,"") -> 142644.2 | K117: =IF(Analysis!$K198,Analysis!F198,"") -> 0.47247541 | L117: =IF(Analysis!$K198,Analysis!G198,"") -> 297 | M117: =IF(Analysis!$K198,Analysis!H198,"") -> 3.9007092 | N117: =IF(Analysis!$K198,Analysis!I198,"") -> 0.14659686
B118: =IF(Analysis!$K199,Analysis!A199,"") -> 5 | C118: =IF(Analysis!$K199,Analysis!B199,"") -> Printed Saree | F118: =IF(Analysis!$K199,Analysis!C199,"") -> Apparel | H118: =IF(Analysis!$K199,Analysis!D199,"") -> 253073.4 | J118: =IF(Analysis!$K199,Analysis!E199,"") -> 123033.4 | K118: =IF(Analysis!$K199,Analysis!F199,"") -> 0.48615698 | L118: =IF(Analysis!$K199,Analysis!G199,"") -> 140 | M118: =IF(Analysis!$K199,Analysis!H199,"") -> 4 | N118: =IF(Analysis!$K199,Analysis!I199,"") -> 0.21276596
B119: =IF(Analysis!$K200,Analysis!A200,"") -> 6 | C119: =IF(Analysis!$K200,Analysis!B200,"") -> Kolhapuri Sandals | F119: =IF(Analysis!$K200,Analysis!C200,"") -> Footwear | H119: =IF(Analysis!$K200,Analysis!D200,"") -> 246453.3 | J119: =IF(Analysis!$K200,Analysis!E200,"") -> 124153.3 | K119: =IF(Analysis!$K200,Analysis!F200,"") -> 0.50375994 | L119: =IF(Analysis!$K200,Analysis!G200,"") -> 272 | M119: =IF(Analysis!$K200,Analysis!H200,"") -> 4.0273973 | N119: =IF(Analysis!$K200,Analysis!I200,"") -> 0.14795918
...

Sheet Detail1
A1: Details for Revenue by Region and Year - State: Odisha, Region: East, Year: 2024
A3: Order ID | B3: Order Date | C3: Year | D3: Month | E3: Month No | F3: Customer ID | G3: Customer Type | H3: State | I3: State Code | J3: Region | K3: City | L3: Sales Channel | M3: Product ID | N3: Product Name | O3: Category | P3: Quantity | Q3: Unit Price | R3: Discount % | S3: Gross Sale | T3: Discount Amount | U3: Net Revenue | V3: Unit Cost | W3: COGS | X3: Shipping Cost | Y3: Profit Margin | Z3: Margin % | AA3: Payment Method | AB3: Delivery Date | AC3: Delivery Days | AD3: Delivery Speed | AE3: Customer Rating | AF3: Returned
A4: ORD-101965 | B4: 45636 | C4: 2024 | D4: 45627 | E4: 12 | F4: CUST-00064 | G4: New | H4: Odisha | I4: OD | J4: East | K4: Bhubaneswar | L4: Myntra | M4: P402 | N4: Casual Sneakers | O4: Footwear | P4: 1 | Q4: 2199 | R4: 0.25 | S4: 2199 | T4: 549.75 | U4: 1649.25 | V4: 1034 | W4: 1034 | X4: 60 | Y4: 555.25 | Z4: 0.33666818 | AA4: Debit Card | AB4: 45640 | AC4: 4 | AD4: Standard (3-4d) | AF4: 0
A5: ORD-101812 | B5: 45613 | C5: 2024 | D5: 45597 | E5: 11 | F5: CUST-01039 | G5: New | H5: Odisha | I5: OD | J5: East | K5: Bhubaneswar | L5: Amazon | M5: P203 | N5: Keratin Hair Mask | O5: Haircare | P5: 1 | Q5: 549 | R5: 0.4 | S5: 549 | T5: 219.6 | U5: 329.4 | V5: 170 | W5: 170 | X5: 60 | Y5: 99.4 | Z5: 0.30176078 | AA5: UPI | AB5: 45618 | AC5: 5 | AD5: Delayed (5d+) | AE5: 4 | AF5: 0
A6: ORD-101718 | B6: 45601 | C6: 2024 | D6: 45597 | E6: 11 | F6: CUST-00149 | G6: New | H6: Odisha | I6: OD | J6: East | K6: Bhubaneswar | L6: Website | M6: P304 | N6: Denim Jacket | O6: Apparel | P6: 1 | Q6: 2499 | R6: 0.1 | S6: 2499 | T6: 249.9 | U6: 2249.1 | V6: 1125 | W6: 1125 | X6: 60 | Y6: 1064.1 | Z6: 0.47312258 | AA6: UPI | AB6: 45604 | AC6: 3 | AD6: Standard (3-4d) | AE6: 4 | AF6: 0
A7: ORD-101705 | B7: 45600 | C7: 2024 | D7: 45597 | E7: 11 | F7: CUST-01532 | G7: New | H7: Odisha | I7: OD | J7: East | K7: Bhubaneswar | L7: Myntra | M7: P301 | N7: Cotton Oversized T-Shirt | O7: Apparel | P7: 1 | Q7: 799 | R7: 0.15 | S7: 799 | T7: 119.85 | U7: 679.15 | V7: 320 | W7: 320 | X7: 120 | Y7: 239.15 | Z7: 0.35213134 | AA7: UPI | AB7: 45604 | AC7: 4 | AD7: Standard (3-4d) | AF7: 1
A8: ORD-100005 | B8: 45292 | C8: 2024 | D8: 45292 | E8: 1 | F8: CUST-01769 | G8: New | H8: Odisha | I8: OD | J8: East | K8: Bhubaneswar | L8: Website | M8: P303 | N8: Joggers | O8: Apparel | P8: 1 | Q8: 1199 | R8: 0.15 | S8: 1199 | T8: 179.85 | U8: 1019.15 | V8: 492 | W8: 492 | X8: 60 | Y8: 467.15 | Z8: 0.45837217 | AA8: Credit Card | AB8: 45298 | AC8: 6 | AD8: Delayed (5d+) | AE8: 3 | AF8: 0
A9: ORD-101651 | B9: 45593 | C9: 2024 | D9: 45566 | E9: 10 | F9: CUST-01243 | G9: New | H9: Odisha | I9: OD | J9: East | K9: Bhubaneswar | L9: Flipkart | M9: P503 | N9: Scented Candle Set | O9: Home & Kitchen | P9: 2 | Q9: 699 | R9: 0.4 | S9: 1398 | T9: 559.2 | U9: 838.8 | V9: 245 | W9: 490 | X9: 60 | Y9: 288.8 | Z9: 0.34430138 | AA9: Wallet | AB9: 45598 | AC9: 5 | AD9: Delayed (5d+) | AE9: 4 | AF9: 0
A10: ORD-101650 | B10: 45593 | C10: 2024 | D10: 45566 | E10: 10 | F10: CUST-01319 | G10: New | H10: Odisha | I10: OD | J10: East | K10: Bhubaneswar | L10: Flipkart | M10: P603 | N10: Smartwatch Strap | O10: Electronics | P10: 1 | Q10: 499 | R10: 0.15 | S10: 499 | T10: 74.85 | U10: 424.15 | V10: 200 | W10: 200 | X10: 60 | Y10: 164.15 | Z10: 0.38700931 | AA10: UPI | AB10: 45598 | AC10: 5 | AD10: Delayed (5d+) | AE10: 4 | AF10: 0
A11: ORD-101517 | B11: 45579 | C11: 2024 | D11: 45566 | E11: 10 | F11: CUST-00121 | G11: Repeat | H11: Odisha | I11: OD | J11: East | K11: Bhubaneswar | L11: Website | M11: P503 | N11: Scented Candle Set | O11: Home & Kitchen | P11: 2 | Q11: 699 | R11: 0.25 | S11: 1398 | T11: 349.5 | U11: 1048.5 | V11: 245 | W11: 490 | X11: 60 | Y11: 498.5 | Z11: 0.47544111 | AA11: UPI | AB11: 45582 | AC11: 3 | AD11: Standard (3-4d) | AE11: 4 | AF11: 0
A12: ORD-101450 | B12: 45572 | C12: 2024 | D12: 45566 | E12: 10 | F12: CUST-02935 | G12: New | H12: Odisha | I12: OD | J12: East | K12: Bhubaneswar | L12: Flipkart | M12: P202 | N12: Argan Shampoo | O12: Haircare | P12: 2 | Q12: 449 | R12: 0.3 | S12: 898 | T12: 269.4 | U12: 628.6 | V12: 148 | W12: 296 | X12: 60 | Y12: 272.6 | Z12: 0.43366211 | AA12: UPI | AB12: 45576 | AC12: 4 | AD12: Standard (3-4d) | AF12: 0
A13: ORD-101369 | B13: 45563 | C13: 2024 | D13: 45536 | E13: 9 | F13: CUST-00535 | G13: Repeat | H13: Odisha | I13: OD | J13: East | K13: Bhubaneswar | L13: Amazon | M13: P105 | N13: Retinol Night Cream | O13: Skincare | P13: 2 | Q13: 799 | R13: 0.05 | S13: 1598 | T13: 79.9 | U13: 1518.1 | V13: 216 | W13: 432 | X13: 60 | Y13: 1026.1 | Z13: 0.67591068 | AA13: UPI | AB13: 45568 | AC13: 5 | AD13: Delayed (5d+) | AE13: 3 | AF13: 0
A14: ORD-101360 | B14: 45562 | C14: 2024 | D14: 45536 | E14: 9 | F14: CUST-01104 | G14: New | H14: Odisha | I14: OD | J14: East | K14: Bhubaneswar | L14: Amazon | M14: P302 | N14: Linen Kurta | O14: Apparel | P14: 2 | Q14: 1499 | R14: 0.3 | S14: 2998 | T14: 899.4 | U14: 2098.6 | V14: 630 | W14: 1260 | X14: 60 | Y14: 778.6 | Z14: 0.37100924 | AA14: UPI | AB14: 45568 | AC14: 6 | AD14: Delayed (5d+) | AE14: 3 | AF14: 0
A15: ORD-101328 | B15: 45556 | C15: 2024 | D15: 45536 | E15: 9 | F15: CUST-01770 | G15: New | H15: Odisha | I15: OD | J15: East | K15: Bhubaneswar | L15: Website | M15: P104 | N15: Hydrating Face Wash | O15: Skincare | P15: 3 | Q15: 299 | R15: 0 | S15: 897 | T15: 0 | U15: 897 | V15: 90 | W15: 270 | X15: 60 | Y15: 567 | Z15: 0.63210702 | AA15: Wallet | AB15: 45559 | AC15: 3 | AD15: Standard (3-4d) | AE15: 3 | AF15: 0
A16: ORD-101178 | B16: 45530 | C16: 2024 | D16: 45505 | E16: 8 | F16: CUST-00940 | G16: Repeat | H16: Odisha | I16: OD | J16: East | K16: Bhubaneswar | L16: Flipkart | M16: P603 | N16: Smartwatch Strap | O16: Electronics | P16: 4 | Q16: 499 | R16: 0.1 | S16: 1996 | T16: 199.6 | U16: 1796.4 | V16: 200 | W16: 800 | X16: 60 | Y16: 936.4 | Z16: 0.52126475 | AA16: Credit Card | AB16: 45533 | AC16: 3 | AD16: Standard (3-4d) | AF16: 0
A17: ORD-101059 | B17: 45505 | C17: 2024 | D17: 45505 | E17: 8 | F17: CUST-00522 | G17: New | H17: Odisha | I17: OD | J17: East | K17: Bhubaneswar | L17: Myntra | M17: P301 | N17: Cotton Oversized T-Shirt | O17: Apparel | P17: 1 | Q17: 799 | R17: 0 | S17: 799 | T17: 0 | U17: 799 | V17: 320 | W17: 320 | X17: 60 | Y17: 419 | Z17: 0.52440551 | AA17: Credit Card | AB17: 45509 | AC17: 4 | AD17: Standard (3-4d) | AE17: 4 | AF17: 0
A18: ORD-100015 | B18: 45294 | C18: 2024 | D18: 45292 | E18: 1 | F18: CUST-00711 | G18: New | H18: Odisha | I18: OD | J18: East | K18: Bhubaneswar | L18: Myntra | M18: P402 | N18: Casual Sneakers | O18: Footwear | P18: 1 | Q18: 2199 | R18: 0.25 | S18: 2199 | T18: 549.75 | U18: 1649.25 | V18: 1034 | W18: 1034 | X18: 60 | Y18: 555.25 | Z18: 0.33666818 | AA18: UPI | AB18: 45300 | AC18: 6 | AD18: Delayed (5d+) | AE18: 4 | AF18: 0
A19: ORD-101007 | B19: 45493 | C19: 2024 | D19: 45474 | E19: 7 | F19: CUST-01084 | G19: Repeat | H19: Odisha | I19: OD | J19: East | K19: Bhubaneswar | L19: Myntra | M19: P403 | N19: Kolhapuri Sandals | O19: Footwear | P19: 1 | Q19: 999 | R19: 0.05 | S19: 999 | T19: 49.95 | U19: 949.05 | V19: 400 | W19: 400 | X19: 60 | Y19: 489.05 | Z19: 0.51530478 | AA19: COD | AB19: 45496 | AC19: 3 | AD19: Standard (3-4d) | AE19: 4 | AF19: 0
A20: ORD-100986 | B20: 45490 | C20: 2024 | D20: 45474 | E20: 7 | F20: CUST-00407 | G20: New | H20: Odisha | I20: OD | J20: East | K20: Bhubaneswar | L20: Nykaa | M20: P204 | N20: Anti-Dandruff Conditioner | O20: Haircare | P20: 2 | Q20: 399 | R20: 0.35 | S20: 798 | T20: 279.3 | U20: 518.7 | V20: 136 | W20: 272 | X20: 60 | Y20: 186.7 | Z20: 0.35993831 | AA20: UPI | AB20: 45493 | AC20: 3 | AD20: Standard (3-4d) | AE20: 3 | AF20: 0
A21: ORD-100985 | B21: 45490 | C21: 2024 | D21: 45474 | E21: 7 | F21: CUST-00709 | G21: New | H21: Odisha | I21: OD | J21: East | K21: Bhubaneswar | L21: Myntra | M21: P302 | N21: Linen Kurta | O21: Apparel | P21: 4 | Q21: 1499 | R21: 0.4 | S21: 5996 | T21: 2398.4 | U21: 3597.6 | V21: 630 | W21: 2520 | X21: 60 | Y21: 1017.6 | Z21: 0.28285524 | AA21: UPI | AB21: 45494 | AC21: 4 | AD21: Standard (3-4d) | AE21: 3 | AF21: 0
A22: ORD-100961 | B22: 45486 | C22: 2024 | D22: 45474 | E22: 7 | F22: CUST-00070 | G22: Repeat | H22: Odisha | I22: OD | J22: East | K22: Bhubaneswar | L22: Website | M22: P604 | N22: Power Bank 20000mAh | O22: Electronics | P22: 1 | Q22: 1799 | R22: 0.35 | S22: 1799 | T22: 629.65 | U22: 1169.35 | V22: 1079 | W22: 1079 | X22: 60 | Y22: 30.35 | Z22: 0.02595459 | AA22: UPI | AB22: 45491 | AC22: 5 | AD22: Delayed (5d+) | AF22: 0
A23: ORD-100924 | B23: 45480 | C23: 2024 | D23: 45474 | E23: 7 | F23: CUST-00809 | G23: Repeat | H23: Odisha | I23: OD | J23: East | K23: Bhubaneswar | L23: Nykaa | M23: P104 | N23: Hydrating Face Wash | O23: Skincare | P23: 1 | Q23: 299 | R23: 0 | S23: 299 | T23: 0 | U23: 299 | V23: 90 | W23: 90 | X23: 60 | Y23: 149 | Z23: 0.49832776 | AA23: UPI | AB23: 45485 | AC23: 5 | AD23: Delayed (5d+) | AE23: 5 | AF23: 0
A24: ORD-100021 | B24: 45295 | C24: 2024 | D24: 45292 | E24: 1 | F24: CUST-00348 | G24: New | H24: Odisha | I24: OD | J24: East | K24: Bhubaneswar | L24: Amazon | M24: P703 | N24: Green Tea (100 bags) | O24: Wellness | P24: 1 | Q24: 399 | R24: 0.3 | S24: 399 | T24: 119.7 | U24: 279.3 | V24: 128 | W24: 128 | X24: 60 | Y24: 91.3 | Z24: 0.32688865 | AA24: UPI | AB24: 45298 | AC24: 3 | AD24: Standard (3-4d) | AE24: 5 | AF24: 0
A25: ORD-100913 | B25: 45479 | C25: 2024 | D25: 45474 | E25: 7 | F25: CUST-00580 | G25: New | H25: Odisha | I25: OD | J25: East | K25: Bhubaneswar | L25: Website | M25: P602 | N25: Fast Charger 33W | O25: Electronics | P25: 2 | Q25: 899 | R25: 0 | S25: 1798 | T25: 0 | U25: 1798 | V25: 494 | W25: 988 | X25: 60 | Y25: 750 | Z25: 0.41713014 | AA25: UPI | AB25: 45484 | AC25: 5 | AD25: Delayed (5d+) | AE25: 3 | AF25: 0
A26: ORD-100808 | B26: 45457 | C26: 2024 | D26: 45444 | E26: 6 | F26: CUST-01100 | G26: New | H26: Odisha | I26: OD | J26: East | K26: Bhubaneswar | L26: Amazon | M26: P103 | N26: Niacinamide Toner | O26: Skincare | P26: 3 | Q26: 399 | R26: 0.15 | S26: 1197 | T26: 179.55 | U26: 1017.45 | V26: 112 | W26: 336 | X26: 60 | Y26: 621.45 | Z26: 0.61079169 | AA26: UPI | AB26: 45463 | AC26: 6 | AD26: Delayed (5d+) | AE26: 3 | AF26: 0
A27: ORD-100766 | B27: 45449 | C27: 2024 | D27: 45444 | E27: 6 | F27: CUST-01116 | G27: Repeat | H27: Odisha | I27: OD | J27: East | K27: Bhubaneswar | L27: Nykaa | M27: P701 | N27: Ashwagandha Capsules | O27: Wellness | P27: 1 | Q27: 499 | R27: 0 | S27: 499 | T27: 0 | U27: 499 | V27: 150 | W27: 150 | X27: 60 | Y27: 289 | Z27: 0.57915832 | AA27: COD | AB27: 45454 | AC27: 5 | AD27: Delayed (5d+) | AE27: 4 | AF27: 0
A28: ORD-100669 | B28: 45430 | C28: 2024 | D28: 45413 | E28: 5 | F28: CUST-03110 | G28: Repeat | H28: Odisha | I28: OD | J28: East | K28: Bhubaneswar | L28: Nykaa | M28: P102 | N28: Sunscreen SPF 50 | O28: Skincare | P28: 3 | Q28: 449 | R28: 0.15 | S28: 1347 | T28: 202.05 | U28: 1144.95 | V28: 144 | W28: 432 | X28: 60 | Y28: 652.95 | Z28: 0.57028691 | AA28: UPI | AB28: 45432 | AC28: 2 | AD28: Express (≤2d) | AF28: 0
A29: ORD-100580 | B29: 45413 | C29: 2024 | D29: 45413 | E29: 5 | F29: CUST-00243 | G29: Repeat | H29: Odisha | I29: OD | J29: East | K29: Bhubaneswar | L29: Nykaa | M29: P104 | N29: Hydrating Face Wash | O29: Skincare | P29: 1 | Q29: 299 | R29: 0.05 | S29: 299 | T29: 14.95 | U29: 284.05 | V29: 90 | W29: 90 | X29: 60 | Y29: 134.05 | Z29: 0.47192396 | AA29: UPI | AB29: 45417 | AC29: 4 | AD29: Standard (3-4d) | AE29: 4 | AF29: 0
A30: ORD-100549 | B30: 45407 | C30: 2024 | D30: 45383 | E30: 4 | F30: CUST-00668 | G30: New | H30: Odisha | I30: OD | J30: East | K30: Bhubaneswar | L30: Myntra | M30: P302 | N30: Linen Kurta | O30: Apparel | P30: 1 | Q30: 1499 | R30: 0.25 | S30: 1499 | T30: 374.75 | U30: 1124.25 | V30: 630 | W30: 630 | X30: 60 | Y30: 434.25 | Z30: 0.38625751 | AA30: UPI | AB30: 45410 | AC30: 3 | AD30: Standard (3-4d) | AF30: 0
A31: ORD-100488 | B31: 45395 | C31: 2024 | D31: 45383 | E31: 4 | F31: CUST-01189 | G31: Repeat | H31: Odisha | I31: OD | J31: East | K31: Bhubaneswar | L31: Website | M31: P601 | N31: Wireless Earbuds | O31: Electronics | P31: 4 | Q31: 1999 | R31: 0.25 | S31: 7996 | T31: 1999 | U31: 5997 | V31: 1239 | W31: 4956 | X31: 60 | Y31: 981 | Z31: 0.16358179 | AA31: Credit Card | AB31: 45401 | AC31: 6 | AD31: Delayed (5d+) | AE31: 3 | AF31: 0
A32: ORD-100465 | B32: 45390 | C32: 2024 | D32: 45383 | E32: 4 | F32: CUST-00597 | G32: Repeat | H32: Odisha | I32: OD | J32: East | K32: Bhubaneswar | L32: Flipkart | M32: P501 | N32: Copper Water Bottle | O32: Home & Kitchen | P32: 1 | Q32: 899 | R32: 0 | S32: 899 | T32: 0 | U32: 899 | V32: 378 | W32: 378 | X32: 60 | Y32: 461 | Z32: 0.51279199 | AA32: Credit Card | AB32: 45395 | AC32: 5 | AD32: Delayed (5d+) | AE32: 4 | AF32: 0
A33: ORD-100456 | B33: 45388 | C33: 2024 | D33: 45383 | E33: 4 | F33: CUST-01527 | G33: New | H33: Odisha | I33: OD | J33: East | K33: Bhubaneswar | L33: Amazon | M33: P703 | N33: Green Tea (100 bags) | O33: Wellness | P33: 2 | Q33: 399 | R33: 0.45 | S33: 798 | T33: 359.1 | U33: 438.9 | V33: 128 | W33: 256 | X33: 60 | Y33: 122.9 | Z33: 0.28001823 | AA33: COD | AB33: 45395 | AC33: 7 | AD33: Delayed (5d+) | AE33: 4 | AF33: 0
A34: ORD-100443 | B34: 45385 | C34: 2024 | D34: 45383 | E34: 4 | F34: CUST-00953 | G34: New | H34: Odisha | I34: OD | J34: East | K34: Bhubaneswar | L34: Flipkart | M34: P702 | N34: Whey Protein 1kg | O34: Wellness | P34: 4 | Q34: 2299 | R34: 0.4 | S34: 9196 | T34: 3678.4 | U34: 5517.6 | V34: 1333 | W34: 5332 | X34: 60 | Y34: 125.6 | Z34: 0.02276352 | AA34: COD | AB34: 45389 | AC34: 4 | AD34: Standard (3-4d) | AE34: 4 | AF34: 0
A35: ORD-100442 | B35: 45385 | C35: 2024 | D35: 45383 | E35: 4 | F35: CUST-00798 | G35: New | H35: Odisha | I35: OD | J35: East | K35: Bhubaneswar | L35: Amazon | M35: P503 | N35: Scented Candle Set | O35: Home & Kitchen | P35: 2 | Q35: 699 | R35: 0.2 | S35: 1398 | T35: 279.6 | U35: 1118.4 | V35: 245 | W35: 490 | X35: 60 | Y35: 568.4 | Z35: 0.50822604 | AA35: UPI | AB35: 45388 | AC35: 3 | AD35: Standard (3-4d) | AE35: 4 | AF35: 0
A36: ORD-100387 | B36: 45372 | C36: 2024 | D36: 45352 | E36: 3 | F36: CUST-01031 | G36: Repeat | H36: Odisha | I36: OD | J36: East | K36: Bhubaneswar | L36: Amazon | M36: P403 | N36: Kolhapuri Sandals | O36: Footwear | P36: 1 | Q36: 999 | R36: 0.1 | S36: 999 | T36: 99.9 | U36: 899.1 | V36: 400 | W36: 400 | X36: 60 | Y36: 439.1 | Z36: 0.48837727 | AA36: Debit Card | AB36: 45378 | AC36: 6 | AD36: Delayed (5d+) | AE36: 4 | AF36: 0
A37: ORD-100379 | B37: 45370 | C37: 2024 | D37: 45352 | E37: 3 | F37: CUST-00414 | G37: New | H37: Odisha | I37: OD | J37: East | K37: Bhubaneswar | L37: Myntra | M37: P301 | N37: Cotton Oversized T-Shirt | O37: Apparel | P37: 2 | Q37: 799 | R37: 0.1 | S37: 1598 | T37: 159.8 | U37: 1438.2 | V37: 320 | W37: 640 | X37: 60 | Y37: 738.2 | Z37: 0.51328049 | AA37: UPI | AB37: 45375 | AC37: 5 | AD37: Delayed (5d+) | AE37: 3 | AF37: 0
A38: ORD-100296 | B38: 45352 | C38: 2024 | D38: 45352 | E38: 3 | F38: CUST-00103 | G38: New | H38: Odisha | I38: OD | J38: East | K38: Bhubaneswar | L38: Amazon | M38: P101 | N38: Vitamin C Face Serum | O38: Skincare | P38: 2 | Q38: 599 | R38: 0.2 | S38: 1198 | T38: 239.6 | U38: 958.4 | V38: 180 | W38: 360 | X38: 60 | Y38: 538.4 | Z38: 0.56176962 | AA38: UPI | AB38: 45355 | AC38: 3 | AD38: Standard (3-4d) | AE38: 4 | AF38: 0
A39: ORD-100188 | B39: 45323 | C39: 2024 | D39: 45323 | E39: 2 | F39: CUST-02705 | G39: New | H39: Odisha | I39: OD | J39: East | K39: Bhubaneswar | L39: Flipkart | M39: P701 | N39: Ashwagandha Capsules | O39: Wellness | P39: 1 | Q39: 499 | R39: 0.05 | S39: 499 | T39: 24.95 | U39: 474.05 | V39: 150 | W39: 150 | X39: 60 | Y39: 264.05 | Z39: 0.55700875 | AA39: UPI | AB39: 45328 | AC39: 5 | AD39: Delayed (5d+) | AF39: 0
A40: ORD-100178 | B40: 45321 | C40: 2024 | D40: 45292 | E40: 1 | F40: CUST-00001 | G40: New | H40: Odisha | I40: OD | J40: East | K40: Bhubaneswar | L40: Amazon | M40: P202 | N40: Argan Shampoo | O40: Haircare | P40: 1 | Q40: 449 | R40: 0.05 | S40: 449 | T40: 22.45 | U40: 426.55 | V40: 148 | W40: 148 | X40: 60 | Y40: 218.55 | Z40: 0.51236666 | AA40: UPI | AB40: 45324 | AC40: 3 | AD40: Standard (3-4d) | AE40: 4 | AF40: 0
A41: ORD-100169 | B41: 45319 | C41: 2024 | D41: 45292 | E41: 1 | F41: CUST-00312 | G41: New | H41: Odisha | I41: OD | J41: East | K41: Bhubaneswar | L41: Myntra | M41: P301 | N41: Cotton Oversized T-Shirt | O41: Apparel | P41: 1 | Q41: 799 | R41: 0.1 | S41: 799 | T41: 79.9 | U41: 719.1 | V41: 320 | W41: 320 | X41: 120 | Y41: 279.1 | Z41: 0.38812404 | AA41: COD | AB41: 45323 | AC41: 4 | AD41: Standard (3-4d) | AE41: 4 | AF41: 1
...

Sheet Analysis
A1: ANALYSIS ENGINE
A3: Filter criteria
A4: cYear | B4: =IF(OR(selYear="All",selYear=""),"<>",selYear) -> <>
A5: cRegion | B5: =IF(OR(selRegion="All",selRegion=""),"<>",selRegion) -> <>
A6: cChannel | B6: =IF(OR(selChannel="All",selChannel=""),"<>",selChannel) -> <>
A7: cCat | B7: =IF(OR(selCategory="All",selCategory=""),"<>",selCategory) -> <>
A9: KPIs
A10: KPI | B10: Selected | C10: 2024 | D10: 2025 | E10: YoY %
A11: Revenue | B11: =SUMIFS(Net_Revenue,Year,cYear,Region,cRegion,Sales_Channel,cChannel,Category,cCat) -> 5156142.5 | C11: =SUMIFS(Net_Revenue,Year,C$10,Region,cRegion,Sales_Channel,cChannel,Category,cCat) -> 2256636.5 | D11: =SUMIFS(Net_Revenue,Year,D$10,Region,cRegion,Sales_Channel,cChannel,Category,cCat) -> 2899506 | E11: =IF(C11=0,"",D11/C11-1) -> 0.28487949
A12: Profit | B12: =SUMIFS(Profit,Year,cYear,Region,cRegion,Sales_Channel,cChannel,Category,cCat) -> 2083254.5 | C12: =SUMIFS(Profit,Year,C$10,Region,cRegion,Sales_Channel,cChannel,Category,cCat) -> 908603.5 | D12: =SUMIFS(Profit,Year,D$10,Region,cRegion,Sales_Channel,cChannel,Category,cCat) -> 1174650.9 | E12: =IF(C12=0,"",D12/C12-1) -> 0.29280918
A13: Margin % | B13: =IFERROR(B12/B11,0) -> 0.40403353 | C13: =IFERROR(C12/C11,0) -> 0.40263618 | D13: =IFERROR(D12/D11,0) -> 0.40512107 | E13: =D13-C13 -> 0.002484889
A14: Orders | B14: =COUNTIFS(Year,cYear,Region,cRegion,Sales_Channel,cChannel,Category,cCat) -> 4833 | C14: =COUNTIFS(Year,C$10,Region,cRegion,Sales_Channel,cChannel,Category,cCat) -> 2126 | D14: =COUNTIFS(Year,D$10,Region,cRegion,Sales_Channel,cChannel,Category,cCat) -> 2707 | E14: =IF(C14=0,"",D14/C14-1) -> 0.27328316
A15: Units | B15: =SUMIFS(Quantity,Year,cYear,Region,cRegion,Sales_Channel,cChannel,Category,cCat) -> 7559 | C15: =SUMIFS(Quantity,Year,C$10,Region,cRegion,Sales_Channel,cChannel,Category,cCat) -> 3303 | D15: =SUMIFS(Quantity,Year,D$10,Region,cRegion,Sales_Channel,cChannel,Category,cCat) -> 4256 | E15: =IF(C15=0,"",D15/C15-1) -> 0.28852558
A16: Avg Order Value | B16: =IFERROR(B11/B14,0) -> 1066.8617 | C16: =IFERROR(C11/C14,0) -> 1061.4471 | D16: =IFERROR(D11/D14,0) -> 1071.1141 | E16: =IF(C16=0,"",D16/C16-1) -> 0.0091074218
A17: Avg Rating | B17: =IFERROR(AVERAGEIFS(Customer_Rating,Year,cYear,Region,cRegion,Sales_Channel,cChannel,Category,cCat),0) -> 3.9144603 | C17: =IFERROR(AVERAGEIFS(Customer_Rating,Year,C$10,Region,cRegion,Sales_Channel,cChannel,Category,cCat),0) -> 3.9201065 | D17: =IFERROR(AVERAGEIFS(Customer_Rating,Year,D$10,Region,cRegion,Sales_Channel,cChannel,Category,cCat),0) -> 3.9100775 | E17: =D17-C17 -> -0.010029005
A18: Return Rate | B18: =IFERROR(SUMIFS(Returned,Year,cYear,Region,cRegion,Sales_Channel,cChannel,Category,cCat)/B14,0) -> 0.10407614 | C18: =IFERROR(SUMIFS(Returned,Year,C$10,Region,cRegion,Sales_Channel,cChannel,Category,cCat)/C14,0) -> 0.10865475 | D18: =IFERROR(SUMIFS(Returned,Year,D$10,Region,cRegion,Sales_Channel,cChannel,Category,cCat)/D14,0) -> 0.10048024 | E18: =D18-C18 -> -0.0081745143 | G18: =IF($K210,$B210,"")
A19: Avg Delivery Days | B19: =IFERROR(AVERAGEIFS(Delivery_Days,Year,cYear,Region,cRegion,Sales_Channel,cChannel,Category,cCat),0) -> 3.3279537 | C19: =IFERROR(AVERAGEIFS(Delivery_Days,Year,C$10,Region,cRegion,Sales_Channel,cChannel,Category,cCat),0) -> 3.3306679 | D19: =IFERROR(AVERAGEIFS(Delivery_Days,Year,D$10,Region,cRegion,Sales_Channel,cChannel,Category,cCat),0) -> 3.3258219 | E19: =D19-C19 -> -0.0048459779
A20: Repeat Customer Revenue % | B20: =IFERROR(SUMIFS(Net_Revenue,Year,cYear,Region,cRegion,Sales_Channel,cChannel,Category,cCat,Customer_Type,"Repeat")/B11,0) -> 0.53148685 | C20: =IFERROR(SUMIFS(Net_Revenue,Year,C$10,Region,cRegion,Sales_Channel,cChannel,Category,cCat,Customer_Type,"Repeat")/C11,0) -> 0.32793192 | D20: =IFERROR(SUMIFS(Net_Revenue,Year,D$10,Region,cRegion,Sales_Channel,cChannel,Category,cCat,Customer_Type,"Repeat")/D11,0) -> 0.68991021 | E20: =D20-C20 -> 0.36197828
A21: Avg Discount % | B21: =IFERROR(SUMIFS(Discount_Amount,Year,cYear,Region,cRegion,Sales_Channel,cChannel,Category,cCat)/SUMIFS(Gross_Sale,Year,cYear,Region,cRegion,Sales_Channel,cChannel,Category,cCat),0) -> 0.21660496 | C21: =IFERROR(SUMIFS(Discount_Amount,Year,C$10,Region,cRegion,Sales_Channel,cChannel,Category,cCat)/SUMIFS(Gross_Sale,Year,C$10,Region,cRegion,Sales_Channel,cChannel,Category,cCat),0) -> 0.21530049 | D21: =IFERROR(SUMIFS(Discount_Amount,Year,D$10,Region,cRegion,Sales_Channel,cChannel,Category,cCat)/SUMIFS(Gross_Sale,Year,D$10,Region,cRegion,Sales_Channel,cChannel,Category,cCat),0) -> 0.2176172 | E21: =D21-C21 -> 0.0023167145
A24: Monthly trend
A25: Month | B25: Revenue | C25: Profit | D25: Margin % | E25: Orders | F25: Avg Order Value | G25: Avg Rating | H25: Return Rate | I25: Avg Delivery Days | J25: Units | K25: Ad Spend
A26: =DATE(2024,1,1) -> 45292 | B26: =SUMIFS(Net_Revenue,Order_Date,">="&$A26,Order_Date,"<"&EDATE($A26,1),Year,cYear,Region,cRegion,Sales_Channel,cChannel,Category,cCat) -> 219793.3 | C26: =SUMIFS(Profit,Order_Date,">="&$A26,Order_Date,"<"&EDATE($A26,1),Year,cYear,Region,cRegion,Sales_Channel,cChannel,Category,cCat) -> 98308.3 | D26: =IFERROR(C26/B26,0) -> 0.44727615 | E26: =COUNTIFS(Order_Date,">="&$A26,Order_Date,"<"&EDATE($A26,1),Year,cYear,Region,cRegion,Sales_Channel,cChannel,Category,cCat) -> 184 | F26: =IFERROR(B26/E26,0) -> 1194.5288 | G26: =IFERROR(AVERAGEIFS(Customer_Rating,Order_Date,">="&$A26,Order_Date,"<"&EDATE($A26,1),Year,cYear,Region,cRegion,Sales_Channel,cChannel,Category,cCat),0) -> 3.9259259 | H26: =IFERROR(SUMIFS(Returned,Order_Date,">="&$A26,Order_Date,"<"&EDATE($A26,1),Year,cYear,Region,cRegion,Sales_Channel,cChannel,Category,cCat)/COUNTIFS(Order_Date,">="&$A26,Order_Date,"<"&EDATE($A26,1),Year,cYear,Region,cRegion,Sales_Channel,cChannel,Category,cCat),0) -> 0.11413043 | I26: =IFERROR(AVERAGEIFS(Delivery_Days,Order_Date,">="&$A26,Order_Date,"<"&EDATE($A26,1),Year,cYear,Region,cRegion,Sales_Channel,cChannel,Category,cCat),0) -> 3.298913 | J26: =SUMIFS(Quantity,Order_Date,">="&$A26,Order_Date,"<"&EDATE($A26,1),Year,cYear,Region,cRegion,Sales_Channel,cChannel,Category,cCat) -> 290 | K26: =SUMIFS(Ad_Spend,Ad_Month,">="&$A26,Ad_Month,"<"&EDATE($A26,1),Ad_Year,cYear,Ad_Region,cRegion) -> 42510
A27: =EDATE(A26,1) -> 45323 | B27: =SUMIFS(Net_Revenue,Order_Date,">="&$A27,Order_Date,"<"&EDATE($A27,1),Year,cYear,Region,cRegion,Sales_Channel,cChannel,Category,cCat) -> 97871.1 | C27: =SUMIFS(Profit,Order_Date,">="&$A27,Order_Date,"<"&EDATE($A27,1),Year,cYear,Region,cRegion,Sales_Channel,cChannel,Category,cCat) -> 43244.1 | D27: =IFERROR(C27/B27,0) -> 0.44184749 | E27: =COUNTIFS(Order_Date,">="&$A27,Order_Date,"<"&EDATE($A27,1),Year,cYear,Region,cRegion,Sales_Channel,cChannel,Category,cCat) -> 107 | F27: =IFERROR(B27/E27,0) -> 914.68318 | G27: =IFERROR(AVERAGEIFS(Customer_Rating,Order_Date,">="&$A27,Order_Date,"<"&EDATE($A27,1),Year,cYear,Region,cRegion,Sales_Channel,cChannel,Category,cCat),0) -> 4 | H27: =IFERROR(SUMIFS(Returned,Order_Date,">="&$A27,Order_Date,"<"&EDATE($A27,1),Year,cYear,Region,cRegion,Sales_Channel,cChannel,Category,cCat)/COUNTIFS(Order_Date,">="&$A27,Order_Date,"<"&EDATE($A27,1),Year,cYear,Region,cRegion,Sales_Channel,cChannel,Category,cCat),0) -> 0.12149533 | I27: =IFERROR(AVERAGEIFS(Delivery_Days,Order_Date,">="&$A27,Order_Date,"<"&EDATE($A27,1),Year,cYear,Region,cRegion,Sales_Channel,cChannel,Category,cCat),0) -> 3.0747664 | J27: =SUMIFS(Quantity,Order_Date,">="&$A27,Order_Date,"<"&EDATE($A27,1),Year,cYear,Region,cRegion,Sales_Channel,cChannel,Category,cCat) -> 162 | K27: =SUMIFS(Ad_Spend,Ad_Month,">="&$A27,Ad_Month,"<"&EDATE($A27,1),Ad_Year,cYear,Ad_Region,cRegion) -> 28210
A28: =EDATE(A27,1) -> 45352 | B28: =SUMIFS(Net_Revenue,Order_Date,">="&$A28,Order_Date,"<"&EDATE($A28,1),Year,cYear,Region,cRegion,Sales_Channel,cChannel,Category,cCat) -> 150200.35 | C28: =SUMIFS(Profit,Order_Date,">="&$A28,Order_Date,"<"&EDATE($A28,1),Year,cYear,Region,cRegion,Sales_Channel,cChannel,Category,cCat) -> 65213.35 | D28: =IFERROR(C28/B28,0) -> 0.43417575 | E28: =COUNTIFS(Order_Date,">="&$A28,Order_Date,"<"&EDATE($A28,1),Year,cYear,Region,cRegion,Sales_Channel,cChannel,Category,cCat) -> 138 | F28: =IFERROR(B28/E28,0) -> 1088.4083 | G28: =IFERROR(AVERAGEIFS(Customer_Rating,Order_Date,">="&$A28,Order_Date,"<"&EDATE($A28,1),Year,cYear,Region,cRegion,Sales_Channel,cChannel,Category,cCat),0) -> 3.9902913 | H28: =IFERROR(SUMIFS(Returned,Order_Date,">="&$A28,Order_Date,"<"&EDATE($A28,1),Year,cYear,Region,cRegion,Sales_Channel,cChannel,Category,cCat)/COUNTIFS(Order_Date,">="&$A28,Order_Date,"<"&EDATE($A28,1),Year,cYear,Region,cRegion,Sales_Channel,cChannel,Category,cCat),0) -> 0.13768116 | I28: =IFERROR(AVERAGEIFS(Delivery_Days,Order_Date,">="&$A28,Order_Date,"<"&EDATE($A28,1),Year,cYear,Region,cRegion,Sales_Channel,cChannel,Category,cCat),0) -> 3.1811594 | J28: =SUMIFS(Quantity,Order_Date,">="&$A28,Order_Date,"<"&EDATE($A28,1),Year,cYear,Region,cRegion,Sales_Channel,cChannel,Category,cCat) -> 220 | K28: =SUMIFS(Ad_Spend,Ad_Month,">="&$A28,Ad_Month,"<"&EDATE($A28,1),Ad_Year,cYear,Ad_Region,cRegion) -> 32350
A29: =EDATE(A28,1) -> 45383 | B29: =SUMIFS(Net_Revenue,Order_Date,">="&$A29,Order_Date,"<"&EDATE($A29,1),Year,cYear,Region,cRegion,Sales_Channel,cChannel,Category,cCat) -> 160817.2 | C29: =SUMIFS(Profit,Order_Date,">="&$A29,Order_Date,"<"&EDATE($A29,1),Year,cYear,Region,cRegion,Sales_Channel,cChannel,Category,cCat) -> 67672.2 | D29: =IFERROR(C29/B29,0) -> 0.420802 | E29: =COUNTIFS(Order_Date,">="&$A29,Order_Date,"<"&EDATE($A29,1),Year,cYear,Region,cRegion,Sales_Channel,cChannel,Category,cCat) -> 146 | F29: =IFERROR(B29/E29,0) -> 1101.4877 | G29: =IFERROR(AVERAGEIFS(Customer_Rating,Order_Date,">="&$A29,Order_Date,"<"&EDATE($A29,1),Year,cYear,Region,cRegion,Sales_Channel,cChannel,Category,cCat),0) -> 4.0291262 | H29: =IFERROR(SUMIFS(Returned,Order_Date,">="&$A29,Order_Date,"<"&EDATE($A29,1),Year,cYear,Region,cRegion,Sales_Channel,cChannel,Category,cCat)/COUNTIFS(Order_Date,">="&$A29,Order_Date,"<"&EDATE($A29,1),Year,cYear,Region,cRegion,Sales_Channel,cChannel,Category,cCat),0) -> 0.089041096 | I29: =IFERROR(AVERAGEIFS(Delivery_Days,Order_Date,">="&$A29,Order_Date,"<"&EDATE($A29,1),Year,cYear,Region,cRegion,Sales_Channel,cChannel,Category,cCat),0) -> 3.2191781 | J29: =SUMIFS(Quantity,Order_Date,">="&$A29,Order_Date,"<"&EDATE($A29,1),Year,cYear,Region,cRegion,Sales_Channel,cChannel,Category,cCat) -> 226 | K29: =SUMIFS(Ad_Spend,Ad_Month,">="&$A29,Ad_Month,"<"&EDATE($A29,1),Ad_Year,cYear,Ad_Region,cRegion) -> 32260
A30: =EDATE(A29,1) -> 45413 | B30: =SUMIFS(Net_Revenue,Order_Date,">="&$A30,Order_Date,"<"&EDATE($A30,1),Year,cYear,Region,cRegion,Sales_Channel,cChannel,Category,cCat) -> 174244.5 | C30: =SUMIFS(Profit,Order_Date,">="&$A30,Order_Date,"<"&EDATE($A30,1),Year,cYear,Region,cRegion,Sales_Channel,cChannel,Category,cCat) -> 73698.5 | D30: =IFERROR(C30/B30,0) -> 0.42296027 | E30: =COUNTIFS(Order_Date,">="&$A30,Order_Date,"<"&EDATE($A30,1),Year,cYear,Region,cRegion,Sales_Channel,cChannel,Category,cCat) -> 155 | F30: =IFERROR(B30/E30,0) -> 1124.1581 | G30: =IFERROR(AVERAGEIFS(Customer_Rating,Order_Date,">="&$A30,Order_Date,"<"&EDATE($A30,1),Year,cYear,Region,cRegion,Sales_Channel,cChannel,Category,cCat),0) -> 4.05 | H30: =IFERROR(SUMIFS(Returned,Order_Date,">="&$A30,Order_Date,"<"&EDATE($A30,1),Year,cYear,Region,cRegion,Sales_Channel,cChannel,Category,cCat)/COUNTIFS(Order_Date,">="&$A30,Order_Date,"<"&EDATE($A30,1),Year,cYear,Region,cRegion,Sales_Channel,cChannel,Category,cCat),0) -> 0.077419355 | I30: =IFERROR(AVERAGEIFS(Delivery_Days,Order_Date,">="&$A30,Order_Date,"<"&EDATE($A30,1),Year,cYear,Region,cRegion,Sales_Channel,cChannel,Category,cCat),0) -> 3.1612903 | J30: =SUMIFS(Quantity,Order_Date,">="&$A30,Order_Date,"<"&EDATE($A30,1),Year,cYear,Region,cRegion,Sales_Channel,cChannel,Category,cCat) -> 242 | K30: =SUMIFS(Ad_Spend,Ad_Month,">="&$A30,Ad_Month,"<"&EDATE($A30,1),Ad_Year,cYear,Ad_Region,cRegion) -> 34050
